<?xml version="1.0" ?>
<robot name="mbot">

    <link name="base_link">
        <visual>
            <origin xyz=" 0 0 0" rpy="0 0 0" />
            <geometry>
                <cylinder length="0.15" radius="0.25"/>
            </geometry>
            <material name="yellow">
                <color rgba="1 0.4 0 1"/>
            </material>
        </visual>
    </link>

    <joint name="A_wheel_joint" type="continuous">
        <origin xyz="0.165 0.095 -0.05" rpy="0 0 -2.6180"/>
        <parent link="base_link"/>
        <child link="A_wheel_link"/>
        <axis xyz="1 0 0"/>
    </joint>

    <link name="A_wheel_link">
        <visual>
            <origin xyz="0 0 0" rpy="1.5707 0 1.5707" />
            <geometry>
                <cylinder radius="0.06" length = "0.025"/>
            </geometry>
            <material name="white">
                <color rgba="1 1 1 0.9"/>
            </material>
        </visual>
    </link>

    <joint name="B_wheel_joint" type="continuous">
       <origin xyz="-0.165 0.095 -0.05" rpy="0 0 -0.523"/>
        <parent link="base_link"/>
        <child link="B_wheel_link"/>
        <axis xyz="1 0 0"/>
    </joint>

    <link name="B_wheel_link">
        <visual>
            <origin xyz="0 0 0" rpy="1.5707 0 1.5707" />
            <geometry>
                <cylinder radius="0.06" length = "0.025"/>
            </geometry>
            <material name="white">
                <color rgba="1 1 1 0.9"/>
            </material>
        </visual>
    </link>

    <joint name="C_wheel_joint" type="continuous">
        <origin xyz="0 -0.19 -0.05" rpy="0 0 1.5707"/>
        <parent link="base_link"/>
        <child link="C_wheel_link"/>
        <axis xyz="1 0 0"/>
    </joint>

    <link name="C_wheel_link">
        <visual>
            <origin xyz="0 0 0" rpy="1.5707 0 1.5707" />
            <geometry>
                <cylinder radius="0.06" length = "0.025"/>
            </geometry>
            <material name="white">
                <color rgba="1 1 1 0.9"/>
            </material>
        </visual>
    </link>

    <link name="laser_link">
		<visual>
			<origin xyz=" 0 0 0 " rpy="0 0 0" />
			<geometry>
				<cylinder length="0.05" radius="0.05"/>
			</geometry>
			<material name="black"/>
		</visual>
    </link>

    <joint name="laser_joint" type="fixed">
        <origin xyz="0 0 0.105" rpy="0 0 0"/>
        <parent link="base_link"/>
        <child link="laser_link"/>
    </joint>

</robot>
